Workbook

Sheet Dashboard
B1: Team Info | C1: xScore | D1: P Chance Win | J1: Book Odds
A2: Home | B2: Newcastle Utd | C2: =P26 -> 0.66225166 | D2: =pDist!O3 -> 0.29883028 | L2: Decimal Odds | M2: Fractional Odds | P2: ML Edge
A3: Away | B3: Arsenal | C3: =Q26 -> 0.67689531 | D3: =pDist!O2 -> 0.30778134 | I3: Home | L3: =M3+1 -> 3.4 | M3: =12/5 -> 2.4
B4: Draw | D4: =pDist!O4 -> 0.39338838 | I4: Away | L4: =M4+1 -> 1.8333333 | M4: =5/6 -> 0.83333333
E10: Monte Carlos
E11: Home | F11: Away | G11: Draw
E12: =COUNTIF(monteCarlo!L:L, "H")/9999 -> 0.70467047 | F12: =COUNTIF(monteCarlo!L:L, "A")/9999 -> 0.29532953 | G12: =COUNTIF(monteCarlo!L:L, "T")/9999 -> 0
E13: =COUNTIF(monteCarlo!Q:Q, "H")/9999 -> 0.7169717 | F13: =COUNTIF(monteCarlo!Q:Q, "A")/9999 -> 0.2830283 | G13: =COUNTIF(monteCarlo!Q:Q, "T")/9999 -> 0
B20: Home | G20: Away
B21: Games Played | C21: Goals scored per game | D21: Goals conceded per game | E21: Attacking strength | F21: Defensive strength | G21: Games Played | H21: Goals scored per game | I21: Goals conceded per game | J21: Attacking strength | K21: Defensive strength
A22: Arsenal | B22: =seasonalStats!B3 -> 5 | C22: =seasonalStats!F3/seasonalStats!B3 -> 2.4 | D22: =seasonalStats!G3/seasonalStats!B3 -> 1.2 | E22: =C22/$C$42 -> 1.6107383 | F22: =D22/$D$42 -> 0.86642599 | G22: =seasonalStats!O3 -> 4 | H22: =seasonalStats!S3/seasonalStats!O3 -> 1.25 | I22: =seasonalStats!T3/seasonalStats!O3 -> 1 | J22: =H22/$H$42 -> 0.88652482 | K22: =I22/$I$42 -> 0.66225166 | P22: Home team | Q22: Away team
A23: Aston Villa | B23: =seasonalStats!B4 -> 5 | C23: =seasonalStats!F4/seasonalStats!B4 -> 1.4 | D23: =seasonalStats!G4/seasonalStats!B4 -> 1.2 | E23: =C23/$C$42 -> 0.93959732 | F23: =D23/$D$42 -> 0.86642599 | G23: =seasonalStats!O4 -> 4 | H23: =seasonalStats!S4/seasonalStats!O4 -> 2.25 | I23: =seasonalStats!T4/seasonalStats!O4 -> 1.25 | J23: =H23/$H$42 -> 1.5957447 | K23: =I23/$I$42 -> 0.82781457 | P23: =B2 -> Newcastle Utd | Q23: =B3 -> Arsenal
A24: Bournemouth | B24: =seasonalStats!B5 -> 4 | C24: =seasonalStats!F5/seasonalStats!B5 -> 1.5 | D24: =seasonalStats!G5/seasonalStats!B5 -> 0.75 | E24: =C24/$C$42 -> 1.0067114 | F24: =D24/$D$42 -> 0.54151625 | G24: =seasonalStats!O5 -> 5 | H24: =seasonalStats!S5/seasonalStats!O5 -> 1 | I24: =seasonalStats!T5/seasonalStats!O5 -> 1.6 | J24: =H24/$H$42 -> 0.70921986 | K24: =I24/$I$42 -> 1.0596026 | O24: Attack strength | P24: =_xlfn.XLOOKUP(P23,A22:A41,E22:E41) -> 0.67114094 | Q24: =_xlfn.XLOOKUP(Q23,A22:A41,J22:J41) -> 0.88652482
A25: Brentford | B25: =seasonalStats!B6 -> 5 | C25: =seasonalStats!F6/seasonalStats!B6 -> 3 | D25: =seasonalStats!G6/seasonalStats!B6 -> 1.8 | E25: =C25/$C$42 -> 2.0134228 | F25: =D25/$D$42 -> 1.299639 | G25: =seasonalStats!O6 -> 4 | H25: =seasonalStats!S6/seasonalStats!O6 -> 0.75 | I25: =seasonalStats!T6/seasonalStats!O6 -> 2.25 | J25: =H25/$H$42 -> 0.53191489 | K25: =I25/$I$42 -> 1.4900662 | O25: Defensive strength | P25: =_xlfn.XLOOKUP(P23,A22:A41,F22:F41) -> 0.54151625 | Q25: =_xlfn.XLOOKUP(Q23,A22:A41,K22:K41) -> 0.66225166
A26: Brighton | B26: =seasonalStats!B7 -> 5 | C26: =seasonalStats!F7/seasonalStats!B7 -> 1.8 | D26: =seasonalStats!G7/seasonalStats!B7 -> 1.4 | E26: =C26/$C$42 -> 1.2080537 | F26: =D26/$D$42 -> 1.0108303 | G26: =seasonalStats!O7 -> 4 | H26: =seasonalStats!S7/seasonalStats!O7 -> 1.75 | I26: =seasonalStats!T7/seasonalStats!O7 -> 1.25 | J26: =H26/$H$42 -> 1.2411348 | K26: =I26/$I$42 -> 0.82781457 | O26: xG | P26: =P24*Q25*C42 -> 0.66225166 | Q26: =Q24*P25*H42 -> 0.67689531
A27: Chelsea | B27: =seasonalStats!B8 -> 5 | C27: =seasonalStats!F8/seasonalStats!B8 -> 1.6 | D27: =seasonalStats!G8/seasonalStats!B8 -> 1.4 | E27: =C27/$C$42 -> 1.0738255 | F27: =D27/$D$42 -> 1.0108303 | G27: =seasonalStats!O8 -> 4 | H27: =seasonalStats!S8/seasonalStats!O8 -> 2.75 | I27: =seasonalStats!T8/seasonalStats!O8 -> 1 | J27: =H27/$H$42 -> 1.9503546 | K27: =I27/$I$42 -> 0.66225166
A28: Crystal Palace | B28: =seasonalStats!B9 -> 5 | C28: =seasonalStats!F9/seasonalStats!B9 -> 0.6 | D28: =seasonalStats!G9/seasonalStats!B9 -> 1 | E28: =C28/$C$42 -> 0.40268456 | F28: =D28/$D$42 -> 0.72202166 | G28: =seasonalStats!O9 -> 4 | H28: =seasonalStats!S9/seasonalStats!O9 -> 0.75 | I28: =seasonalStats!T9/seasonalStats!O9 -> 1.5 | J28: =H28/$H$42 -> 0.53191489 | K28: =I28/$I$42 -> 0.99337748
A29: Everton | B29: =seasonalStats!B10 -> 5 | C29: =seasonalStats!F10/seasonalStats!B10 -> 1 | D29: =seasonalStats!G10/seasonalStats!B10 -> 1.6 | E29: =C29/$C$42 -> 0.67114094 | F29: =D29/$D$42 -> 1.1552347 | G29: =seasonalStats!O10 -> 4 | H29: =seasonalStats!S10/seasonalStats!O10 -> 1.25 | I29: =seasonalStats!T10/seasonalStats!O10 -> 2 | J29: =H29/$H$42 -> 0.88652482 | K29: =I29/$I$42 -> 1.3245033
A30: Fulham | B30: =seasonalStats!B11 -> 4 | C30: =seasonalStats!F11/seasonalStats!B11 -> 1.75 | D30: =seasonalStats!G11/seasonalStats!B11 -> 1.5 | E30: =C30/$C$42 -> 1.1744966 | F30: =D30/$D$42 -> 1.0830325 | G30: =seasonalStats!O11 -> 5 | H30: =seasonalStats!S11/seasonalStats!O11 -> 1 | I30: =seasonalStats!T11/seasonalStats!O11 -> 1.2 | J30: =H30/$H$42 -> 0.70921986 | K30: =I30/$I$42 -> 0.79470199
A31: Ipswich Town | B31: =seasonalStats!B12 -> 4 | C31: =seasonalStats!F12/seasonalStats!B12 -> 0.75 | D31: =seasonalStats!G12/seasonalStats!B12 -> 1.75 | E31: =C31/$C$42 -> 0.5033557 | F31: =D31/$D$42 -> 1.2635379 | G31: =seasonalStats!O12 -> 5 | H31: =seasonalStats!S12/seasonalStats!O12 -> 1.2 | I31: =seasonalStats!T12/seasonalStats!O12 -> 2.6 | J31: =H31/$H$42 -> 0.85106383 | K31: =I31/$I$42 -> 1.7218543
A32: Leicester City | B32: =seasonalStats!B13 -> 5 | C32: =seasonalStats!F13/seasonalStats!B13 -> 1 | D32: =seasonalStats!G13/seasonalStats!B13 -> 1.4 | E32: =C32/$C$42 -> 0.67114094 | F32: =D32/$D$42 -> 1.0108303 | G32: =seasonalStats!O13 -> 4 | H32: =seasonalStats!S13/seasonalStats!O13 -> 2 | I32: =seasonalStats!T13/seasonalStats!O13 -> 2.5 | J32: =H32/$H$42 -> 1.4184397 | K32: =I32/$I$42 -> 1.6556291
A33: Liverpool | B33: =seasonalStats!B14 -> 4 | C33: =seasonalStats!F14/seasonalStats!B14 -> 1.75 | D33: =seasonalStats!G14/seasonalStats!B14 -> 0.5 | E33: =C33/$C$42 -> 1.1744966 | F33: =D33/$D$42 -> 0.36101083 | G33: =seasonalStats!O14 -> 5 | H33: =seasonalStats!S14/seasonalStats!O14 -> 2 | I33: =seasonalStats!T14/seasonalStats!O14 -> 0.6 | J33: =H33/$H$42 -> 1.4184397 | K33: =I33/$I$42 -> 0.39735099
A34: Manchester City | B34: =seasonalStats!B15 -> 5 | C34: =seasonalStats!F15/seasonalStats!B15 -> 2.4 | D34: =seasonalStats!G15/seasonalStats!B15 -> 1.2 | E34: =C34/$C$42 -> 1.6107383 | F34: =D34/$D$42 -> 0.86642599 | G34: =seasonalStats!O15 -> 4 | H34: =seasonalStats!S15/seasonalStats!O15 -> 2 | I34: =seasonalStats!T15/seasonalStats!O15 -> 0.75 | J34: =H34/$H$42 -> 1.4184397 | K34: =I34/$I$42 -> 0.49668874
A35: Manchester Utd | B35: =seasonalStats!B16 -> 4 | C35: =seasonalStats!F16/seasonalStats!B16 -> 0.75 | D35: =seasonalStats!G16/seasonalStats!B16 -> 1.75 | E35: =C35/$C$42 -> 0.5033557 | F35: =D35/$D$42 -> 1.2635379 | G35: =seasonalStats!O16 -> 5 | H35: =seasonalStats!S16/seasonalStats!O16 -> 1 | I35: =seasonalStats!T16/seasonalStats!O16 -> 0.8 | J35: =H35/$H$42 -> 0.70921986 | K35: =I35/$I$42 -> 0.52980132
A36: Newcastle Utd | B36: =seasonalStats!B17 -> 4 | C36: =seasonalStats!F17/seasonalStats!B17 -> 1 | D36: =seasonalStats!G17/seasonalStats!B17 -> 0.75 | E36: =C36/$C$42 -> 0.67114094 | F36: =D36/$D$42 -> 0.54151625 | G36: =seasonalStats!O17 -> 5 | H36: =seasonalStats!S17/seasonalStats!O17 -> 1 | I36: =seasonalStats!T17/seasonalStats!O17 -> 1.4 | J36: =H36/$H$42 -> 0.70921986 | K36: =I36/$I$42 -> 0.92715232
A37: Nott'ham Forest | B37: =seasonalStats!B18 -> 4 | C37: =seasonalStats!F18/seasonalStats!B18 -> 0.75 | D37: =seasonalStats!G18/seasonalStats!B18 -> 0.75 | E37: =C37/$C$42 -> 0.5033557 | F37: =D37/$D$42 -> 0.54151625 | G37: =seasonalStats!O18 -> 5 | H37: =seasonalStats!S18/seasonalStats!O18 -> 1.6 | I37: =seasonalStats!T18/seasonalStats!O18 -> 0.8 | J37: =H37/$H$42 -> 1.1347518 | K37: =I37/$I$42 -> 0.52980132
A38: Southampton | B38: =seasonalStats!B19 -> 4 | C38: =seasonalStats!F19/seasonalStats!B19 -> 0.75 | D38: =seasonalStats!G19/seasonalStats!B19 -> 2 | E38: =C38/$C$42 -> 0.5033557 | F38: =D38/$D$42 -> 1.4440433 | G38: =seasonalStats!O19 -> 5 | H38: =seasonalStats!S19/seasonalStats!O19 -> 0.6 | I38: =seasonalStats!T19/seasonalStats!O19 -> 2.2 | J38: =H38/$H$42 -> 0.42553191 | K38: =I38/$I$42 -> 1.4569536
... A41: Wolves | B41: =seasonalStats!B22 -> 4 | C41: =seasonalStats!F22/seasonalStats!B22 -> 1.25 | D41: =seasonalStats!G22/seasonalStats!B22 -> 3 | E41: =C41/$C$42 -> 0.83892617 | F41: =D41/$D$42 -> 2.166065 | G41: =seasonalStats!O22 -> 5 | H41: =seasonalStats!S22/seasonalStats!O22 -> 1.4 | I41: =seasonalStats!T22/seasonalStats!O22 -> 2.6 | J41: =H41/$H$42 -> 0.9929078 | K41: =I41/$I$42 -> 1.7218543
C42: =AVERAGE(C22:C41) -> 1.49 | D42: =AVERAGE(D22:D41) -> 1.385 | H42: =AVERAGE(H22:H41) -> 1.41 | I42: =AVERAGE(I22:I41) -> 1.51

Sheet monteCarlo
A1: Team | B1: Average Earned | C1: Average Allowed | D1: Adjusted Score | F1: Standard Deviation | G1: % Chance to Win | I1: Scenario | J1: Away | K1: Home | L1: Outcome | N1: Scenario | O1: Away | P1: Home | Q1: Outcome
A2: =Dashboard!B2 -> Newcastle Utd | B2: =INDIRECT("averageStats!d2:d21"&MATCH(A2, averageStats!A2:A21, 0)) -> 2.3 | C2: =INDIRECT("averageStats!e2:e21"&MATCH(A2, averageStats!A2:A21, 0)) -> 0.8 | D2: =SQRT(B2*C3) -> 1.6192591 | F2: =STDEV(INDIRECT("homeStats!J"&MATCH(A2,homeStats!D:D,0)):INDIRECT("'homeStats'!J"&COUNTIF(homeStats!D:D,A2)+MATCH(A2,homeStats!D:D,0)-1)) -> 0.81649658 | I2: 1 | J2: =NORMINV(RAND(), $D$3,$F$3) -> 0.088695114 | K2: =NORMINV(RAND(), $D$2,$F$2) -> 2.5760778 | L2: =IF(J2>K2, "A", IF(J2=K2, "T", "H")) -> H | N2: 1 | O2: =NORMINV(RAND(), $D$11,$F$11) -> 0.13902107 | P2: =NORMINV(RAND(), $D$10,$F$10) -> 0.58654519 | Q2: =IF(O2>P2, "A", IF(O2=P2, "T", "H")) -> H
A3: =Dashboard!B3 -> Arsenal | B3: =INDIRECT("averageStats!b2:b21"&MATCH(A3, averageStats!A2:A21, 0)) -> 1.16 | C3: =INDIRECT("averageStats!c2:c21"&MATCH(A3, averageStats!A2:A21, 0)) -> 1.14 | D3: =SQRT(B3*C2) -> 0.96332757 | F3: =STDEV(INDIRECT("awayStats!K"&MATCH(A3, awayStats!H:H, 0)):INDIRECT("'awayStats'!K"&COUNTIF(awayStats!H:H,A3)+MATCH(A3,awayStats!H:H,0)-1)) -> 0.95742711 | I3: 2 | J3: =NORMINV(RAND(), $D$3,$F$3) -> 2.7706558 | K3: =NORMINV(RAND(), $D$2,$F$2) -> 1.5692082 | L3: =IF(J3>K3, "A", IF(J3=K3, "T", "H")) -> A | N3: =N2+1 -> 2 | O3: =NORMINV(RAND(), $D$11,$F$11) -> 0.6607528 | P3: =NORMINV(RAND(), $D$10,$F$10) -> 2.1223278 | Q3: =IF(O3>P3, "A", IF(O3=P3, "T", "H")) -> H
I4: 3 | J4: =NORMINV(RAND(), $D$3,$F$3) -> -1.4919875 | K4: =NORMINV(RAND(), $D$2,$F$2) -> 1.6625741 | L4: =IF(J4>K4, "A", IF(J4=K4, "T", "H")) -> H | N4: =N3+1 -> 3 | O4: =NORMINV(RAND(), $D$11,$F$11) -> 1.8250103 | P4: =NORMINV(RAND(), $D$10,$F$10) -> 1.023446 | Q4: =IF(O4>P4, "A", IF(O4=P4, "T", "H")) -> A
I5: 4 | J5: =NORMINV(RAND(), $D$3,$F$3) -> 1.1213777 | K5: =NORMINV(RAND(), $D$2,$F$2) -> 3.503064 | L5: =IF(J5>K5, "A", IF(J5=K5, "T", "H")) -> H | N5: =N4+1 -> 4 | O5: =NORMINV(RAND(), $D$11,$F$11) -> 0.72187115 | P5: =NORMINV(RAND(), $D$10,$F$10) -> 1.0869427 | Q5: =IF(O5>P5, "A", IF(O5=P5, "T", "H")) -> H
I6: 5 | J6: =NORMINV(RAND(), $D$3,$F$3) -> 1.1443383 | K6: =NORMINV(RAND(), $D$2,$F$2) -> 1.4372271 | L6: =IF(J6>K6, "A", IF(J6=K6, "T", "H")) -> H | N6: =N5+1 -> 5 | O6: =NORMINV(RAND(), $D$11,$F$11) -> 1.7862821 | P6: =NORMINV(RAND(), $D$10,$F$10) -> 0.75220317 | Q6: =IF(O6>P6, "A", IF(O6=P6, "T", "H")) -> A
I7: 6 | J7: =NORMINV(RAND(), $D$3,$F$3) -> 0.02081136 | K7: =NORMINV(RAND(), $D$2,$F$2) -> 1.4308081 | L7: =IF(J7>K7, "A", IF(J7=K7, "T", "H")) -> H | N7: =N6+1 -> 6 | O7: =NORMINV(RAND(), $D$11,$F$11) -> 1.4185562 | P7: =NORMINV(RAND(), $D$10,$F$10) -> 0.27325656 | Q7: =IF(O7>P7, "A", IF(O7=P7, "T", "H")) -> A
I8: 7 | J8: =NORMINV(RAND(), $D$3,$F$3) -> 0.84902459 | K8: =NORMINV(RAND(), $D$2,$F$2) -> 1.3545966 | L8: =IF(J8>K8, "A", IF(J8=K8, "T", "H")) -> H | N8: =N7+1 -> 7 | O8: =NORMINV(RAND(), $D$11,$F$11) -> 2.2120553 | P8: =NORMINV(RAND(), $D$10,$F$10) -> 0.38279581 | Q8: =IF(O8>P8, "A", IF(O8=P8, "T", "H")) -> A
A9: Team | B9: Average Earned | C9: Average Allowed | D9: Adjusted Score | F9: Standard Deviation | G9: % Chance to Win | I9: 8 | J9: =NORMINV(RAND(), $D$3,$F$3) -> 0.13090526 | K9: =NORMINV(RAND(), $D$2,$F$2) -> 0.92485462 | L9: =IF(J9>K9, "A", IF(J9=K9, "T", "H")) -> H | N9: =N8+1 -> 8 | O9: =NORMINV(RAND(), $D$11,$F$11) -> 1.1895055 | P9: =NORMINV(RAND(), $D$10,$F$10) -> -0.28601686 | Q9: =IF(O9>P9, "A", IF(O9=P9, "T", "H")) -> A
A10: =Dashboard!B2 -> Newcastle Utd | B10: =B2 -> 2.3 | C10: =C2 -> 0.8 | D10: =(B10/teamStats!M3)*(monteCarlo!C10/teamStats!N3)*teamStats!M3 -> 1.3248 | F10: =STDEV(INDIRECT("homeStats!J"&MATCH(A10, homeStats!D:D, 0)):INDIRECT("'homeStats'!J"&COUNTIF(homeStats!D:D,A10)+MATCH(A10, homeStats!D:D, 0)-1)) -> 0.81649658 | I10: 9 | J10: =NORMINV(RAND(), $D$3,$F$3) -> 1.9044673 | K10: =NORMINV(RAND(), $D$2,$F$2) -> 2.003496 | L10: =IF(J10>K10, "A", IF(J10=K10, "T", "H")) -> H | N10: =N9+1 -> 9 | O10: =NORMINV(RAND(), $D$11,$F$11) -> 0.57423561 | P10: =NORMINV(RAND(), $D$10,$F$10) -> 1.5084105 | Q10: =IF(O10>P10, "A", IF(O10=P10, "T", "H")) -> H
A11: =Dashboard!B3 -> Arsenal | B11: =B3 -> 1.16 | C11: =C3 -> 1.14 | D11: =(B11/teamStats!O3)*(monteCarlo!C10/teamStats!P3)*teamStats!O3 -> 0.61411765 | F11: =STDEV(INDIRECT("awayStats!K"&MATCH(A11, awayStats!H:H, 0)):INDIRECT("'awayStats'!K"&COUNTIF(awayStats!H:H,A11)+MATCH(A11, awayStats!H:H, 0)-1)) -> 0.95742711 | I11: 10 | J11: =NORMINV(RAND(), $D$3,$F$3) -> 1.2311306 | K11: =NORMINV(RAND(), $D$2,$F$2) -> 1.9254039 | L11: =IF(J11>K11, "A", IF(J11=K11, "T", "H")) -> H | N11: =N10+1 -> 10 | O11: =NORMINV(RAND(), $D$11,$F$11) -> 1.008936 | P11: =NORMINV(RAND(), $D$10,$F$10) -> 2.2000575 | Q11: =IF(O11>P11, "A", IF(O11=P11, "T", "H")) -> H
I12: 11 | J12: =NORMINV(RAND(), $D$3,$F$3) -> -1.1056858 | K12: =NORMINV(RAND(), $D$2,$F$2) -> 2.1071107 | L12: =IF(J12>K12, "A", IF(J12=K12, "T", "H")) -> H | N12: =N11+1 -> 11 | O12: =NORMINV(RAND(), $D$11,$F$11) -> 1.0742998 | P12: =NORMINV(RAND(), $D$10,$F$10) -> 0.093437104 | Q12: =IF(O12>P12, "A", IF(O12=P12, "T", "H")) -> A
I13: 12 | J13: =NORMINV(RAND(), $D$3,$F$3) -> 2.1641097 | K13: =NORMINV(RAND(), $D$2,$F$2) -> 1.8260398 | L13: =IF(J13>K13, "A", IF(J13=K13, "T", "H")) -> A | N13: =N12+1 -> 12 | O13: =NORMINV(RAND(), $D$11,$F$11) -> 1.6336937 | P13: =NORMINV(RAND(), $D$10,$F$10) -> -0.44828377 | Q13: =IF(O13>P13, "A", IF(O13=P13, "T", "H")) -> A
I14: 13 | J14: =NORMINV(RAND(), $D$3,$F$3) -> 0.080349026 | K14: =NORMINV(RAND(), $D$2,$F$2) -> 1.1175078 | L14: =IF(J14>K14, "A", IF(J14=K14, "T", "H")) -> H | N14: =N13+1 -> 13 | O14: =NORMINV(RAND(), $D$11,$F$11) -> 0.45643921 | P14: =NORMINV(RAND(), $D$10,$F$10) -> 2.5978961 | Q14: =IF(O14>P14, "A", IF(O14=P14, "T", "H")) -> H
I15: 14 | J15: =NORMINV(RAND(), $D$3,$F$3) -> 1.6408658 | K15: =NORMINV(RAND(), $D$2,$F$2) -> 3.0777473 | L15: =IF(J15>K15, "A", IF(J15=K15, "T", "H")) -> H | N15: =N14+1 -> 14 | O15: =NORMINV(RAND(), $D$11,$F$11) -> -0.45924051 | P15: =NORMINV(RAND(), $D$10,$F$10) -> 1.5496726 | Q15: =IF(O15>P15, "A", IF(O15=P15, "T", "H")) -> H
I16: 15 | J16: =NORMINV(RAND(), $D$3,$F$3) -> 1.6237065 | K16: =NORMINV(RAND(), $D$2,$F$2) -> 1.7324512 | L16: =IF(J16>K16, "A", IF(J16=K16, "T", "H")) -> H | N16: =N15+1 -> 15 | O16: =NORMINV(RAND(), $D$11,$F$11) -> 0.56421434 | P16: =NORMINV(RAND(), $D$10,$F$10) -> 1.1897489 | Q16: =IF(O16>P16, "A", IF(O16=P16, "T", "H")) -> H
I17: 16 | J17: =NORMINV(RAND(), $D$3,$F$3) -> 1.6578842 | K17: =NORMINV(RAND(), $D$2,$F$2) -> 1.1221135 | L17: =IF(J17>K17, "A", IF(J17=K17, "T", "H")) -> A | N17: =N16+1 -> 16 | O17: =NORMINV(RAND(), $D$11,$F$11) -> 0.1331008 | P17: =NORMINV(RAND(), $D$10,$F$10) -> 1.8549333 | Q17: =IF(O17>P17, "A", IF(O17=P17, "T", "H")) -> H
I18: 17 | J18: =NORMINV(RAND(), $D$3,$F$3) -> 0.31927586 | K18: =NORMINV(RAND(), $D$2,$F$2) -> 3.0806065 | L18: =IF(J18>K18, "A", IF(J18=K18, "T", "H")) -> H | N18: =N17+1 -> 17 | O18: =NORMINV(RAND(), $D$11,$F$11) -> 1.0888065 | P18: =NORMINV(RAND(), $D$10,$F$10) -> 1.0362656 | Q18: =IF(O18>P18, "A", IF(O18=P18, "T", "H")) -> A
I19: 18 | J19: =NORMINV(RAND(), $D$3,$F$3) -> 0.83617083 | K19: =NORMINV(RAND(), $D$2,$F$2) -> 1.6364801 | L19: =IF(J19>K19, "A", IF(J19=K19, "T", "H")) -> H | N19: =N18+1 -> 18 | O19: =NORMINV(RAND(), $D$11,$F$11) -> 0.34975071 | P19: =NORMINV(RAND(), $D$10,$F$10) -> 1.009963 | Q19: =IF(O19>P19, "A", IF(O19=P19, "T", "H")) -> H
I20: 19 | J20: =NORMINV(RAND(), $D$3,$F$3) -> 0.99540772 | K20: =NORMINV(RAND(), $D$2,$F$2) -> 2.5805708 | L20: =IF(J20>K20, "A", IF(J20=K20, "T", "H")) -> H | N20: =N19+1 -> 19 | O20: =NORMINV(RAND(), $D$11,$F$11) -> 0.77138336 | P20: =NORMINV(RAND(), $D$10,$F$10) -> 1.0546478 | Q20: =IF(O20>P20, "A", IF(O20=P20, "T", "H")) -> H
I21: 20 | J21: =NORMINV(RAND(), $D$3,$F$3) -> 1.788774 | K21: =NORMINV(RAND(), $D$2,$F$2) -> 1.7502601 | L21: =IF(J21>K21, "A", IF(J21=K21, "T", "H")) -> A | N21: =N20+1 -> 20 | O21: =NORMINV(RAND(), $D$11,$F$11) -> 1.5449619 | P21: =NORMINV(RAND(), $D$10,$F$10) -> 1.9136331 | Q21: =IF(O21>P21, "A", IF(O21=P21, "T", "H")) -> H
I22: 21 | J22: =NORMINV(RAND(), $D$3,$F$3) -> 1.1600905 | K22: =NORMINV(RAND(), $D$2,$F$2) -> 0.83355609 | L22: =IF(J22>K22, "A", IF(J22=K22, "T", "H")) -> A | N22: =N21+1 -> 21 | O22: =NORMINV(RAND(), $D$11,$F$11) -> 0.49553455 | P22: =NORMINV(RAND(), $D$10,$F$10) -> 1.3191529 | Q22: =IF(O22>P22, "A", IF(O22=P22, "T", "H")) -> H
I23: 22 | J23: =NORMINV(RAND(), $D$3,$F$3) -> 1.1164666 | K23: =NORMINV(RAND(), $D$2,$F$2) -> 1.9783818 | L23: =IF(J23>K23, "A", IF(J23=K23, "T", "H")) -> H | N23: =N22+1 -> 22 | O23: =NORMINV(RAND(), $D$11,$F$11) -> 1.2693922 | P23: =NORMINV(RAND(), $D$10,$F$10) -> 1.8891304 | Q23: =IF(O23>P23, "A", IF(O23=P23, "T", "H")) -> H
... I10000: 9999 | J10000: =NORMINV(RAND(), $D$3,$F$3) -> -0.084613266 | K10000: =NORMINV(RAND(), $D$2,$F$2) -> 1.3211812 | L10000: =IF(J10000>K10000, "A", IF(J10000=K10000, "T", "H")) -> H | N10000: =N9999+1 -> 9999 | O10000: =NORMINV(RAND(), $D$11,$F$11) -> 1.4455971 | P10000: =NORMINV(RAND(), $D$10,$F$10) -> 2.2047714 | Q10000: =IF(O10000>P10000, "A", IF(O10000=P10000, "T", "H")) -> H

Sheet teamStats
A1: Wk | B1: Day | C1: Date | D1: Home | E1: xG | F1: Score | G1: xGa | H1: Away | I1: Venue | J1: Home goals | K1: Away goals | M1: Home | O1: Away
A2: 1 | B2: Fri | C2: 2024-08-16 | D2: Manchester Utd | E2: 2.4 | F2: 1–0 | G2: 0.4 | H2: Fulham | I2: Old Trafford | J2: =IF(F2<>"", VALUE(LEFT(SUBSTITUTE(F2, "–", "-"), FIND("-", SUBSTITUTE(F2, "–", "-")) - 1)), "") -> 1 | K2: =IF(F2<>"", VALUE(RIGHT(SUBSTITUTE(F2, "–", "-"), LEN(SUBSTITUTE(F2, "–", "-")) - FIND("-", SUBSTITUTE(F2, "–", "-")))), "") -> 0 | M2: Average for | N2: Average against | O2: Average for | P2: Average against
A3: 1 | B3: Sat | C3: 2024-08-17 | D3: Ipswich Town | E3: 0.5 | F3: 0–2 | G3: 2.6 | H3: Liverpool | I3: Portman Road Stadium | J3: =IF(F3<>"", VALUE(LEFT(SUBSTITUTE(F3, "–", "-"), FIND("-", SUBSTITUTE(F3, "–", "-")) - 1)), "") -> 0 | K3: =IF(F3<>"", VALUE(RIGHT(SUBSTITUTE(F3, "–", "-"), LEN(SUBSTITUTE(F3, "–", "-")) - FIND("-", SUBSTITUTE(F3, "–", "-")))), "") -> 2 | M3: =AVERAGE(J2:J381) -> 1.5111111 | N3: =AVERAGE(K2:K381) -> 1.3888889 | O3: =AVERAGE(K2:K381) -> 1.3888889 | P3: =AVERAGE(J2:J381) -> 1.5111111
A4: 1 | B4: Sat | C4: 2024-08-17 | D4: Newcastle Utd | E4: 0.3 | F4: 1–0 | G4: 1.8 | H4: Southampton | I4: St James' Park | J4: =IF(F4<>"", VALUE(LEFT(SUBSTITUTE(F4, "–", "-"), FIND("-", SUBSTITUTE(F4, "–", "-")) - 1)), "") -> 1 | K4: =IF(F4<>"", VALUE(RIGHT(SUBSTITUTE(F4, "–", "-"), LEN(SUBSTITUTE(F4, "–", "-")) - FIND("-", SUBSTITUTE(F4, "–", "-")))), "") -> 0
A5: 1 | B5: Sat | C5: 2024-08-17 | D5: Nott'ham Forest | E5: 1.3 | F5: 1–1 | G5: 1.2 | H5: Bournemouth | I5: The City Ground | J5: =IF(F5<>"", VALUE(LEFT(SUBSTITUTE(F5, "–", "-"), FIND("-", SUBSTITUTE(F5, "–", "-")) - 1)), "") -> 1 | K5: =IF(F5<>"", VALUE(RIGHT(SUBSTITUTE(F5, "–", "-"), LEN(SUBSTITUTE(F5, "–", "-")) - FIND("-", SUBSTITUTE(F5, "–", "-")))), "") -> 1
A6: 1 | B6: Sat | C6: 2024-08-17 | D6: Everton | E6: 0.5 | F6: 0–3 | G6: 1.4 | H6: Brighton | I6: Goodison Park | J6: =IF(F6<>"", VALUE(LEFT(SUBSTITUTE(F6, "–", "-"), FIND("-", SUBSTITUTE(F6, "–", "-")) - 1)), "") -> 0 | K6: =IF(F6<>"", VALUE(RIGHT(SUBSTITUTE(F6, "–", "-"), LEN(SUBSTITUTE(F6, "–", "-")) - FIND("-", SUBSTITUTE(F6, "–", "-")))), "") -> 3
A7: 1 | B7: Sat | C7: 2024-08-17 | D7: Arsenal | E7: 1.2 | F7: 2–0 | G7: 0.5 | H7: Wolves | I7: Emirates Stadium | J7: =IF(F7<>"", VALUE(LEFT(SUBSTITUTE(F7, "–", "-"), FIND("-", SUBSTITUTE(F7, "–", "-")) - 1)), "") -> 2 | K7: =IF(F7<>"", VALUE(RIGHT(SUBSTITUTE(F7, "–", "-"), LEN(SUBSTITUTE(F7, "–", "-")) - FIND("-", SUBSTITUTE(F7, "–", "-")))), "") -> 0
A8: 1 | B8: Sat | C8: 2024-08-17 | D8: West Ham | E8: 2.3 | F8: 1–2 | G8: 2.0 | H8: Aston Villa | I8: London Stadium | J8: =IF(F8<>"", VALUE(LEFT(SUBSTITUTE(F8, "–", "-"), FIND("-", SUBSTITUTE(F8, "–", "-")) - 1)), "") -> 1 | K8: =IF(F8<>"", VALUE(RIGHT(SUBSTITUTE(F8, "–", "-"), LEN(SUBSTITUTE(F8, "–", "-")) - FIND("-", SUBSTITUTE(F8, "–", "-")))), "") -> 2
A9: 1 | B9: Sun | C9: 2024-08-18 | D9: Brentford | E9: 1.6 | F9: 2–1 | G9: 1.2 | H9: Crystal Palace | I9: Gtech Community Stadium | J9: =IF(F9<>"", VALUE(LEFT(SUBSTITUTE(F9, "–", "-"), FIND("-", SUBSTITUTE(F9, "–", "-")) - 1)), "") -> 2 | K9: =IF(F9<>"", VALUE(RIGHT(SUBSTITUTE(F9, "–", "-"), LEN(SUBSTITUTE(F9, "–", "-")) - FIND("-", SUBSTITUTE(F9, "–", "-")))), "") -> 1
A10: 1 | B10: Sun | C10: 2024-08-18 | D10: Chelsea | E10: 1.0 | F10: 0–2 | G10: 0.8 | H10: Manchester City | I10: Stamford Bridge | J10: =IF(F10<>"", VALUE(LEFT(SUBSTITUTE(F10, "–", "-"), FIND("-", SUBSTITUTE(F10, "–", "-")) - 1)), "") -> 0 | K10: =IF(F10<>"", VALUE(RIGHT(SUBSTITUTE(F10, "–", "-"), LEN(SUBSTITUTE(F10, "–", "-")) - FIND("-", SUBSTITUTE(F10, "–", "-")))), "") -> 2
A11: 1 | B11: Mon | C11: 2024-08-19 | D11: Leicester City | E11: 1.0 | F11: 1–1 | G11: 1.2 | H11: Tottenham | I11: King Power Stadium | J11: =IF(F11<>"", VALUE(LEFT(SUBSTITUTE(F11, "–", "-"), FIND("-", SUBSTITUTE(F11, "–", "-")) - 1)), "") -> 1 | K11: =IF(F11<>"", VALUE(RIGHT(SUBSTITUTE(F11, "–", "-"), LEN(SUBSTITUTE(F11, "–", "-")) - FIND("-", SUBSTITUTE(F11, "–", "-")))), "") -> 1
A12: 2 | B12: Sat | C12: 2024-08-24 | D12: Brighton | E12: 2.1 | F12: 2–1 | G12: 1.4 | H12: Manchester Utd | I12: The American Express Stadium | J12: =IF(F12<>"", VALUE(LEFT(SUBSTITUTE(F12, "–", "-"), FIND("-", SUBSTITUTE(F12, "–", "-")) - 1)), "") -> 2 | K12: =IF(F12<>"", VALUE(RIGHT(SUBSTITUTE(F12, "–", "-"), LEN(SUBSTITUTE(F12, "–", "-")) - FIND("-", SUBSTITUTE(F12, "–", "-")))), "") -> 1
A13: 2 | B13: Sat | C13: 2024-08-24 | D13: Tottenham | E13: 2.4 | F13: 4–0 | G13: 1.0 | H13: Everton | I13: Tottenham Hotspur Stadium | J13: =IF(F13<>"", VALUE(LEFT(SUBSTITUTE(F13, "–", "-"), FIND("-", SUBSTITUTE(F13, "–", "-")) - 1)), "") -> 4 | K13: =IF(F13<>"", VALUE(RIGHT(SUBSTITUTE(F13, "–", "-"), LEN(SUBSTITUTE(F13, "–", "-")) - FIND("-", SUBSTITUTE(F13, "–", "-")))), "") -> 0
A14: 2 | B14: Sat | C14: 2024-08-24 | D14: Fulham | E14: 1.8 | F14: 2–1 | G14: 0.6 | H14: Leicester City | I14: Craven Cottage | J14: =IF(F14<>"", VALUE(LEFT(SUBSTITUTE(F14, "–", "-"), FIND("-", SUBSTITUTE(F14, "–", "-")) - 1)), "") -> 2 | K14: =IF(F14<>"", VALUE(RIGHT(SUBSTITUTE(F14, "–", "-"), LEN(SUBSTITUTE(F14, "–", "-")) - FIND("-", SUBSTITUTE(F14, "–", "-")))), "") -> 1
A15: 2 | B15: Sat | C15: 2024-08-24 | D15: Crystal Palace | E15: 1.3 | F15: 0–2 | G15: 1.4 | H15: West Ham | I15: Selhurst Park | J15: =IF(F15<>"", VALUE(LEFT(SUBSTITUTE(F15, "–", "-"), FIND("-", SUBSTITUTE(F15, "–", "-")) - 1)), "") -> 0 | K15: =IF(F15<>"", VALUE(RIGHT(SUBSTITUTE(F15, "–", "-"), LEN(SUBSTITUTE(F15, "–", "-")) - FIND("-", SUBSTITUTE(F15, "–", "-")))), "") -> 2
... A91: 9 | B91: Sun | C91: 2024-10-27 | D91: Arsenal | E91: 0.9 | F91: 2–2 | G91: 0.8 | H91: Liverpool | I91: Emirates Stadium | J91: =IF(F91<>"", VALUE(LEFT(SUBSTITUTE(F91, "–", "-"), FIND("-", SUBSTITUTE(F91, "–", "-")) - 1)), "") -> 2 | K91: =IF(F91<>"", VALUE(RIGHT(SUBSTITUTE(F91, "–", "-"), LEN(SUBSTITUTE(F91, "–", "-")) - FIND("-", SUBSTITUTE(F91, "–", "-")))), "") -> 2
A92: 10 | B92: Sat | C92: 2024-11-02 | D92: Newcastle Utd | H92: Arsenal | I92: St James' Park | J92: =IF(F92<>"", VALUE(LEFT(SUBSTITUTE(F92, "–", "-"), FIND("-", SUBSTITUTE(F92, "–", "-")) - 1)), "") | K92: =IF(F92<>"", VALUE(RIGHT(SUBSTITUTE(F92, "–", "-"), LEN(SUBSTITUTE(F92, "–", "-")) - FIND("-", SUBSTITUTE(F92, "–", "-")))), "")
A93: 10 | B93: Sat | C93: 2024-11-02 | D93: Southampton | H93: Everton | I93: St Mary's Stadium | J93: =IF(F93<>"", VALUE(LEFT(SUBSTITUTE(F93, "–", "-"), FIND("-", SUBSTITUTE(F93, "–", "-")) - 1)), "") | K93: =IF(F93<>"", VALUE(RIGHT(SUBSTITUTE(F93, "–", "-"), LEN(SUBSTITUTE(F93, "–", "-")) - FIND("-", SUBSTITUTE(F93, "–", "-")))), "")
A94: 10 | B94: Sat | C94: 2024-11-02 | D94: Liverpool | H94: Brighton | I94: Anfield | J94: =IF(F94<>"", VALUE(LEFT(SUBSTITUTE(F94, "–", "-"), FIND("-", SUBSTITUTE(F94, "–", "-")) - 1)), "") | K94: =IF(F94<>"", VALUE(RIGHT(SUBSTITUTE(F94, "–", "-"), LEN(SUBSTITUTE(F94, "–", "-")) - FIND("-", SUBSTITUTE(F94, "–", "-")))), "")
A95: 10 | B95: Sat | C95: 2024-11-02 | D95: Nott'ham Forest | H95: West Ham | I95: The City Ground | J95: =IF(F95<>"", VALUE(LEFT(SUBSTITUTE(F95, "–", "-"), FIND("-", SUBSTITUTE(F95, "–", "-")) - 1)), "") | K95: =IF(F95<>"", VALUE(RIGHT(SUBSTITUTE(F95, "–", "-"), LEN(SUBSTITUTE(F95, "–", "-")) - FIND("-", SUBSTITUTE(F95, "–", "-")))), "")
A96: 10 | B96: Sat | C96: 2024-11-02 | D96: Ipswich Town | H96: Leicester City | I96: Portman Road Stadium | J96: =IF(F96<>"", VALUE(LEFT(SUBSTITUTE(F96, "–", "-"), FIND("-", SUBSTITUTE(F96, "–", "-")) - 1)), "") | K96: =IF(F96<>"", VALUE(RIGHT(SUBSTITUTE(F96, "–", "-"), LEN(SUBSTITUTE(F96, "–", "-")) - FIND("-", SUBSTITUTE(F96, "–", "-")))), "")
A97: 10 | B97: Sat | C97: 2024-11-02 | D97: Bournemouth | H97: Manchester City | I97: Vitality Stadium | J97: =IF(F97<>"", VALUE(LEFT(SUBSTITUTE(F97, "–", "-"), FIND("-", SUBSTITUTE(F97, "–", "-")) - 1)), "") | K97: =IF(F97<>"", VALUE(RIGHT(SUBSTITUTE(F97, "–", "-"), LEN(SUBSTITUTE(F97, "–", "-")) - FIND("-", SUBSTITUTE(F97, "–", "-")))), "")
A98: 10 | B98: Sat | C98: 2024-11-02 | D98: Wolves | H98: Crystal Palace | I98: Molineux Stadium | J98: =IF(F98<>"", VALUE(LEFT(SUBSTITUTE(F98, "–", "-"), FIND("-", SUBSTITUTE(F98, "–", "-")) - 1)), "") | K98: =IF(F98<>"", VALUE(RIGHT(SUBSTITUTE(F98, "–", "-"), LEN(SUBSTITUTE(F98, "–", "-")) - FIND("-", SUBSTITUTE(F98, "–", "-")))), "")
A99: 10 | B99: Sun | C99: 2024-11-03 | D99: Tottenham | H99: Aston Villa | I99: Tottenham Hotspur Stadium | J99: =IF(F99<>"", VALUE(LEFT(SUBSTITUTE(F99, "–", "-"), FIND("-", SUBSTITUTE(F99, "–", "-")) - 1)), "") | K99: =IF(F99<>"", VALUE(RIGHT(SUBSTITUTE(F99, "–", "-"), LEN(SUBSTITUTE(F99, "–", "-")) - FIND("-", SUBSTITUTE(F99, "–", "-")))), "")
A100: 10 | B100: Sun | C100: 2024-11-03 | D100: Manchester Utd | H100: Chelsea | I100: Old Trafford | J100: =IF(F100<>"", VALUE(LEFT(SUBSTITUTE(F100, "–", "-"), FIND("-", SUBSTITUTE(F100, "–", "-")) - 1)), "") | K100: =IF(F100<>"", VALUE(RIGHT(SUBSTITUTE(F100, "–", "-"), LEN(SUBSTITUTE(F100, "–", "-")) - FIND("-", SUBSTITUTE(F100, "–", "-")))), "")
A101: 10 | B101: Mon | C101: 2024-11-04 | D101: Fulham | H101: Brentford | I101: Craven Cottage | J101: =IF(F101<>"", VALUE(LEFT(SUBSTITUTE(F101, "–", "-"), FIND("-", SUBSTITUTE(F101, "–", "-")) - 1)), "") | K101: =IF(F101<>"", VALUE(RIGHT(SUBSTITUTE(F101, "–", "-"), LEN(SUBSTITUTE(F101, "–", "-")) - FIND("-", SUBSTITUTE(F101, "–", "-")))), "")
A102: 11 | B102: Sat | C102: 2024-11-09 | D102: Brentford | H102: Bournemouth | I102: Gtech Community Stadium | J102: =IF(F102<>"", VALUE(LEFT(SUBSTITUTE(F102, "–", "-"), FIND("-", SUBSTITUTE(F102, "–", "-")) - 1)), "") | K102: =IF(F102<>"", VALUE(RIGHT(SUBSTITUTE(F102, "–", "-"), LEN(SUBSTITUTE(F102, "–", "-")) - FIND("-", SUBSTITUTE(F102, "–", "-")))), "")
A103: 11 | B103: Sat | C103: 2024-11-09 | D103: West Ham | H103: Everton | I103: London Stadium | J103: =IF(F103<>"", VALUE(LEFT(SUBSTITUTE(F103, "–", "-"), FIND("-", SUBSTITUTE(F103, "–", "-")) - 1)), "") | K103: =IF(F103<>"", VALUE(RIGHT(SUBSTITUTE(F103, "–", "-"), LEN(SUBSTITUTE(F103, "–", "-")) - FIND("-", SUBSTITUTE(F103, "–", "-")))), "")
... A381: 38 | B381: Sun | C381: 2025-05-25 | D381: Tottenham | H381: Brighton | I381: Tottenham Hotspur Stadium | J381: =IF(F381<>"", VALUE(LEFT(SUBSTITUTE(F381, "–", "-"), FIND("-", SUBSTITUTE(F381, "–", "-")) - 1)), "") | K381: =IF(F381<>"", VALUE(RIGHT(SUBSTITUTE(F381, "–", "-"), LEN(SUBSTITUTE(F381, "–", "-")) - FIND("-", SUBSTITUTE(F381, "–", "-")))), "")

Sheet homeStats2
A1: Wk | B1: Day | C1: Date | D1: Home | E1: xG | F1: Score | G1: xGa | H1: Away | I1: Venue | J1: Home goals | K1: Away goals | L1: Row number | N1: Home | P1: Away
A2: 6 | B2: Sat | C2: 2024-09-28 | D2: Arsenal | E2: 4.4 | F2: 4–2 | G2: 0.3 | H2: Leicester City | I2: Emirates Stadium | J2: =IF(F2<>"", VALUE(LEFT(SUBSTITUTE(F2, "–", "-"), FIND("-", SUBSTITUTE(F2, "–", "-")) - 1)), "") -> 4 | K2: =IF(F2<>"", VALUE(RIGHT(SUBSTITUTE(F2, "–", "-"), LEN(SUBSTITUTE(F2, "–", "-")) - FIND("-", SUBSTITUTE(F2, "–", "-")))), "") -> 2 | L2: 2 | N2: Average for | O2: Average against | P2: Average for | Q2: Average against
A3: 30 | B3: Tue | C3: 2025-04-01 | D3: Arsenal | H3: Fulham | I3: Emirates Stadium | J3: =IF(F3<>"", VALUE(LEFT(SUBSTITUTE(F3, "–", "-"), FIND("-", SUBSTITUTE(F3, "–", "-")) - 1)), "") | K3: =IF(F3<>"", VALUE(RIGHT(SUBSTITUTE(F3, "–", "-"), LEN(SUBSTITUTE(F3, "–", "-")) - FIND("-", SUBSTITUTE(F3, "–", "-")))), "") | L3: =L2+1 -> 3 | N3: =AVERAGE(J2:J381) -> 1.5111111 | O3: =AVERAGE(K2:K381) -> 1.3888889 | P3: =AVERAGE(K2:K381) -> 1.3888889 | Q3: =AVERAGE(J2:J381) -> 1.5111111
A4: 35 | B4: Sat | C4: 2025-05-03 | D4: Arsenal | H4: Bournemouth | I4: Emirates Stadium | J4: =IF(F4<>"", VALUE(LEFT(SUBSTITUTE(F4, "–", "-"), FIND("-", SUBSTITUTE(F4, "–", "-")) - 1)), "") | K4: =IF(F4<>"", VALUE(RIGHT(SUBSTITUTE(F4, "–", "-"), LEN(SUBSTITUTE(F4, "–", "-")) - FIND("-", SUBSTITUTE(F4, "–", "-")))), "") | L4: =L3+1 -> 4
A5: 18 | B5: Fri | C5: 2024-12-27 | D5: Arsenal | H5: Ipswich Town | I5: Emirates Stadium | J5: =IF(F5<>"", VALUE(LEFT(SUBSTITUTE(F5, "–", "-"), FIND("-", SUBSTITUTE(F5, "–", "-")) - 1)), "") | K5: =IF(F5<>"", VALUE(RIGHT(SUBSTITUTE(F5, "–", "-"), LEN(SUBSTITUTE(F5, "–", "-")) - FIND("-", SUBSTITUTE(F5, "–", "-")))), "") | L5: =L4+1 -> 5
A6: 16 | B6: Sat | C6: 2024-12-14 | D6: Arsenal | H6: Everton | I6: Emirates Stadium | J6: =IF(F6<>"", VALUE(LEFT(SUBSTITUTE(F6, "–", "-"), FIND("-", SUBSTITUTE(F6, "–", "-")) - 1)), "") | K6: =IF(F6<>"", VALUE(RIGHT(SUBSTITUTE(F6, "–", "-"), LEN(SUBSTITUTE(F6, "–", "-")) - FIND("-", SUBSTITUTE(F6, "–", "-")))), "") | L6: =L5+1 -> 6
A7: 37 | B7: Sun | C7: 2025-05-18 | D7: Arsenal | H7: Newcastle Utd | I7: Emirates Stadium | J7: =IF(F7<>"", VALUE(LEFT(SUBSTITUTE(F7, "–", "-"), FIND("-", SUBSTITUTE(F7, "–", "-")) - 1)), "") | K7: =IF(F7<>"", VALUE(RIGHT(SUBSTITUTE(F7, "–", "-"), LEN(SUBSTITUTE(F7, "–", "-")) - FIND("-", SUBSTITUTE(F7, "–", "-")))), "") | L7: =L6+1 -> 7
A8: 29 | B8: Sat | C8: 2025-03-15 | D8: Arsenal | H8: Chelsea | I8: Emirates Stadium | J8: =IF(F8<>"", VALUE(LEFT(SUBSTITUTE(F8, "–", "-"), FIND("-", SUBSTITUTE(F8, "–", "-")) - 1)), "") | K8: =IF(F8<>"", VALUE(RIGHT(SUBSTITUTE(F8, "–", "-"), LEN(SUBSTITUTE(F8, "–", "-")) - FIND("-", SUBSTITUTE(F8, "–", "-")))), "") | L8: =L7+1 -> 8
A9: 21 | B9: Wed | C9: 2025-01-15 | D9: Arsenal | H9: Tottenham | I9: Emirates Stadium | J9: =IF(F9<>"", VALUE(LEFT(SUBSTITUTE(F9, "–", "-"), FIND("-", SUBSTITUTE(F9, "–", "-")) - 1)), "") | K9: =IF(F9<>"", VALUE(RIGHT(SUBSTITUTE(F9, "–", "-"), LEN(SUBSTITUTE(F9, "–", "-")) - FIND("-", SUBSTITUTE(F9, "–", "-")))), "") | L9: =L8+1 -> 9
A10: 14 | B10: Wed | C10: 2024-12-04 | D10: Arsenal | H10: Manchester Utd | I10: Emirates Stadium | J10: =IF(F10<>"", VALUE(LEFT(SUBSTITUTE(F10, "–", "-"), FIND("-", SUBSTITUTE(F10, "–", "-")) - 1)), "") | K10: =IF(F10<>"", VALUE(RIGHT(SUBSTITUTE(F10, "–", "-"), LEN(SUBSTITUTE(F10, "–", "-")) - FIND("-", SUBSTITUTE(F10, "–", "-")))), "") | L10: =L9+1 -> 10
A11: 32 | B11: Sat | C11: 2025-04-12 | D11: Arsenal | H11: Brentford | I11: Emirates Stadium | J11: =IF(F11<>"", VALUE(LEFT(SUBSTITUTE(F11, "–", "-"), FIND("-", SUBSTITUTE(F11, "–", "-")) - 1)), "") | K11: =IF(F11<>"", VALUE(RIGHT(SUBSTITUTE(F11, "–", "-"), LEN(SUBSTITUTE(F11, "–", "-")) - FIND("-", SUBSTITUTE(F11, "–", "-")))), "") | L11: =L10+1 -> 11
A12: 22 | B12: Sat | C12: 2025-01-18 | D12: Arsenal | H12: Aston Villa | I12: Emirates Stadium | J12: =IF(F12<>"", VALUE(LEFT(SUBSTITUTE(F12, "–", "-"), FIND("-", SUBSTITUTE(F12, "–", "-")) - 1)), "") | K12: =IF(F12<>"", VALUE(RIGHT(SUBSTITUTE(F12, "–", "-"), LEN(SUBSTITUTE(F12, "–", "-")) - FIND("-", SUBSTITUTE(F12, "–", "-")))), "") | L12: =L11+1 -> 12
A13: 9 | B13: Sun | C13: 2024-10-27 | D13: Arsenal | E13: 0.9 | F13: 2–2 | G13: 0.8 | H13: Liverpool | I13: Emirates Stadium | J13: =IF(F13<>"", VALUE(LEFT(SUBSTITUTE(F13, "–", "-"), FIND("-", SUBSTITUTE(F13, "–", "-")) - 1)), "") -> 2 | K13: =IF(F13<>"", VALUE(RIGHT(SUBSTITUTE(F13, "–", "-"), LEN(SUBSTITUTE(F13, "–", "-")) - FIND("-", SUBSTITUTE(F13, "–", "-")))), "") -> 2 | L13: =L12+1 -> 13
A14: 3 | B14: Sat | C14: 2024-08-31 | D14: Arsenal | E14: 2.1 | F14: 1–1 | G14: 1.7 | H14: Brighton | I14: Emirates Stadium | J14: =IF(F14<>"", VALUE(LEFT(SUBSTITUTE(F14, "–", "-"), FIND("-", SUBSTITUTE(F14, "–", "-")) - 1)), "") -> 1 | K14: =IF(F14<>"", VALUE(RIGHT(SUBSTITUTE(F14, "–", "-"), LEN(SUBSTITUTE(F14, "–", "-")) - FIND("-", SUBSTITUTE(F14, "–", "-")))), "") -> 1 | L14: =L13+1 -> 14
A15: 24 | B15: Sat | C15: 2025-02-01 | D15: Arsenal | H15: Manchester City | I15: Emirates Stadium | J15: =IF(F15<>"", VALUE(LEFT(SUBSTITUTE(F15, "–", "-"), FIND("-", SUBSTITUTE(F15, "–", "-")) - 1)), "") | K15: =IF(F15<>"", VALUE(RIGHT(SUBSTITUTE(F15, "–", "-"), LEN(SUBSTITUTE(F15, "–", "-")) - FIND("-", SUBSTITUTE(F15, "–", "-")))), "") | L15: =L14+1 -> 15
A16: 7 | B16: Sat | C16: 2024-10-05 | D16: Arsenal | E16: 2.8 | F16: 3–1 | G16: 0.6 | H16: Southampton | I16: Emirates Stadium | J16: =IF(F16<>"", VALUE(LEFT(SUBSTITUTE(F16, "–", "-"), FIND("-", SUBSTITUTE(F16, "–", "-")) - 1)), "") -> 3 | K16: =IF(F16<>"", VALUE(RIGHT(SUBSTITUTE(F16, "–", "-"), LEN(SUBSTITUTE(F16, "–", "-")) - FIND("-", SUBSTITUTE(F16, "–", "-")))), "") -> 1 | L16: =L15+1 -> 16
A17: 1 | B17: Sat | C17: 2024-08-17 | D17: Arsenal | E17: 1.2 | F17: 2–0 | G17: 0.5 | H17: Wolves | I17: Emirates Stadium | J17: =IF(F17<>"", VALUE(LEFT(SUBSTITUTE(F17, "–", "-"), FIND("-", SUBSTITUTE(F17, "–", "-")) - 1)), "") -> 2 | K17: =IF(F17<>"", VALUE(RIGHT(SUBSTITUTE(F17, "–", "-"), LEN(SUBSTITUTE(F17, "–", "-")) - FIND("-", SUBSTITUTE(F17, "–", "-")))), "") -> 0 | L17: =L16+1 -> 17
A18: 12 | B18: Sat | C18: 2024-11-23 | D18: Arsenal | H18: Nott'ham Forest | I18: Emirates Stadium | J18: =IF(F18<>"", VALUE(LEFT(SUBSTITUTE(F18, "–", "-"), FIND("-", SUBSTITUTE(F18, "–", "-")) - 1)), "") | K18: =IF(F18<>"", VALUE(RIGHT(SUBSTITUTE(F18, "–", "-"), LEN(SUBSTITUTE(F18, "–", "-")) - FIND("-", SUBSTITUTE(F18, "–", "-")))), "") | L18: =L17+1 -> 18
A19: 26 | B19: Sat | C19: 2025-02-22 | D19: Arsenal | H19: West Ham | I19: Emirates Stadium | J19: =IF(F19<>"", VALUE(LEFT(SUBSTITUTE(F19, "–", "-"), FIND("-", SUBSTITUTE(F19, "–", "-")) - 1)), "") | K19: =IF(F19<>"", VALUE(RIGHT(SUBSTITUTE(F19, "–", "-"), LEN(SUBSTITUTE(F19, "–", "-")) - FIND("-", SUBSTITUTE(F19, "–", "-")))), "") | L19: =L18+1 -> 19
A20: 34 | B20: Sat | C20: 2025-04-26 | D20: Arsenal | H20: Crystal Palace | I20: Emirates Stadium | J20: =IF(F20<>"", VALUE(LEFT(SUBSTITUTE(F20, "–", "-"), FIND("-", SUBSTITUTE(F20, "–", "-")) - 1)), "") | K20: =IF(F20<>"", VALUE(RIGHT(SUBSTITUTE(F20, "–", "-"), LEN(SUBSTITUTE(F20, "–", "-")) - FIND("-", SUBSTITUTE(F20, "–", "-")))), "") | L20: =L19+1 -> 20
A21: 7 | B21: Sun | C21: 2024-10-06 | D21: Aston Villa | E21: 0.5 | F21: 0–0 | G21: 0.6 | H21: Manchester Utd | I21: Villa Park | J21: =IF(F21<>"", VALUE(LEFT(SUBSTITUTE(F21, "–", "-"), FIND("-", SUBSTITUTE(F21, "–", "-")) - 1)), "") -> 0 | K21: =IF(F21<>"", VALUE(RIGHT(SUBSTITUTE(F21, "–", "-"), LEN(SUBSTITUTE(F21, "–", "-")) - FIND("-", SUBSTITUTE(F21, "–", "-")))), "") -> 0 | L21: =L20+1 -> 21
A22: 35 | B22: Sat | C22: 2025-05-03 | D22: Aston Villa | H22: Fulham | I22: Villa Park | J22: =IF(F22<>"", VALUE(LEFT(SUBSTITUTE(F22, "–", "-"), FIND("-", SUBSTITUTE(F22, "–", "-")) - 1)), "") | K22: =IF(F22<>"", VALUE(RIGHT(SUBSTITUTE(F22, "–", "-"), LEN(SUBSTITUTE(F22, "–", "-")) - FIND("-", SUBSTITUTE(F22, "–", "-")))), "") | L22: =L21+1 -> 22
A23: 26 | B23: Sat | C23: 2025-02-22 | D23: Aston Villa | H23: Chelsea | I23: Villa Park | J23: =IF(F23<>"", VALUE(LEFT(SUBSTITUTE(F23, "–", "-"), FIND("-", SUBSTITUTE(F23, "–", "-")) - 1)), "") | K23: =IF(F23<>"", VALUE(RIGHT(SUBSTITUTE(F23, "–", "-"), LEN(SUBSTITUTE(F23, "–", "-")) - FIND("-", SUBSTITUTE(F23, "–", "-")))), "") | L23: =L22+1 -> 23
A24: 33 | B24: Sat | C24: 2025-04-19 | D24: Aston Villa | H24: Newcastle Utd | I24: Villa Park | J24: =IF(F24<>"", VALUE(LEFT(SUBSTITUTE(F24, "–", "-"), FIND("-", SUBSTITUTE(F24, "–", "-")) - 1)), "") | K24: =IF(F24<>"", VALUE(RIGHT(SUBSTITUTE(F24, "–", "-"), LEN(SUBSTITUTE(F24, "–", "-")) - FIND("-", SUBSTITUTE(F24, "–", "-")))), "") | L24: =L23+1 -> 24
A25: 31 | B25: Sat | C25: 2025-04-05 | D25: Aston Villa | H25: Nott'ham Forest | I25: Villa Park | J25: =IF(F25<>"", VALUE(LEFT(SUBSTITUTE(F25, "–", "-"), FIND("-", SUBSTITUTE(F25, "–", "-")) - 1)), "") | K25: =IF(F25<>"", VALUE(RIGHT(SUBSTITUTE(F25, "–", "-"), LEN(SUBSTITUTE(F25, "–", "-")) - FIND("-", SUBSTITUTE(F25, "–", "-")))), "") | L25: =L24+1 -> 25
A26: 19 | B26: Mon | C26: 2024-12-30 | D26: Aston Villa | H26: Brighton | I26: Villa Park | J26: =IF(F26<>"", VALUE(LEFT(SUBSTITUTE(F26, "–", "-"), FIND("-", SUBSTITUTE(F26, "–", "-")) - 1)), "") | K26: =IF(F26<>"", VALUE(RIGHT(SUBSTITUTE(F26, "–", "-"), LEN(SUBSTITUTE(F26, "–", "-")) - FIND("-", SUBSTITUTE(F26, "–", "-")))), "") | L26: =L25+1 -> 26
A27: 5 | B27: Sat | C27: 2024-09-21 | D27: Aston Villa | E27: 1.7 | F27: 3–1 | G27: 0.5 | H27: Wolves | I27: Villa Park | J27: =IF(F27<>"", VALUE(LEFT(SUBSTITUTE(F27, "–", "-"), FIND("-", SUBSTITUTE(F27, "–", "-")) - 1)), "") -> 3 | K27: =IF(F27<>"", VALUE(RIGHT(SUBSTITUTE(F27, "–", "-"), LEN(SUBSTITUTE(F27, "–", "-")) - FIND("-", SUBSTITUTE(F27, "–", "-")))), "") -> 1 | L27: =L26+1 -> 27
A28: 20 | B28: Sat | C28: 2025-01-04 | D28: Aston Villa | H28: Leicester City | I28: Villa Park | J28: =IF(F28<>"", VALUE(LEFT(SUBSTITUTE(F28, "–", "-"), FIND("-", SUBSTITUTE(F28, "–", "-")) - 1)), "") | K28: =IF(F28<>"", VALUE(RIGHT(SUBSTITUTE(F28, "–", "-"), LEN(SUBSTITUTE(F28, "–", "-")) - FIND("-", SUBSTITUTE(F28, "–", "-")))), "") | L28: =L27+1 -> 28
A29: 29 | B29: Sat | C29: 2025-03-15 | D29: Aston Villa | H29: Liverpool | I29: Villa Park | J29: =IF(F29<>"", VALUE(LEFT(SUBSTITUTE(F29, "–", "-"), FIND("-", SUBSTITUTE(F29, "–", "-")) - 1)), "") | K29: =IF(F29<>"", VALUE(RIGHT(SUBSTITUTE(F29, "–", "-"), LEN(SUBSTITUTE(F29, "–", "-")) - FIND("-", SUBSTITUTE(F29, "–", "-")))), "") | L29: =L28+1 -> 29
A30: 15 | B30: Sat | C30: 2024-12-07 | D30: Aston Villa | H30: Southampton | I30: Villa Park | J30: =IF(F30<>"", VALUE(LEFT(SUBSTITUTE(F30, "–", "-"), FIND("-", SUBSTITUTE(F30, "–", "-")) - 1)), "") | K30: =IF(F30<>"", VALUE(RIGHT(SUBSTITUTE(F30, "–", "-"), LEN(SUBSTITUTE(F30, "–", "-")) - FIND("-", SUBSTITUTE(F30, "–", "-")))), "") | L30: =L29+1 -> 30
A31: 4 | B31: Sat | C31: 2024-09-14 | D31: Aston Villa | E31: 2.1 | F31: 3–2 | G31: 0.9 | H31: Everton | I31: Villa Park | J31: =IF(F31<>"", VALUE(LEFT(SUBSTITUTE(F31, "–", "-"), FIND("-", SUBSTITUTE(F31, "–", "-")) - 1)), "") -> 3 | K31: =IF(F31<>"", VALUE(RIGHT(SUBSTITUTE(F31, "–", "-"), LEN(SUBSTITUTE(F31, "–", "-")) - FIND("-", SUBSTITUTE(F31, "–", "-")))), "") -> 2 | L31: =L30+1 -> 31
A32: 17 | B32: Sat | C32: 2024-12-21 | D32: Aston Villa | H32: Manchester City | I32: Villa Park | J32: =IF(F32<>"", VALUE(LEFT(SUBSTITUTE(F32, "–", "-"), FIND("-", SUBSTITUTE(F32, "–", "-")) - 1)), "") | K32: =IF(F32<>"", VALUE(RIGHT(SUBSTITUTE(F32, "–", "-"), LEN(SUBSTITUTE(F32, "–", "-")) - FIND("-", SUBSTITUTE(F32, "–", "-")))), "") | L32: =L31+1 -> 32
A33: 14 | B33: Wed | C33: 2024-12-04 | D33: Aston Villa | H33: Brentford | I33: Villa Park | J33: =IF(F33<>"", VALUE(LEFT(SUBSTITUTE(F33, "–", "-"), FIND("-", SUBSTITUTE(F33, "–", "-")) - 1)), "") | K33: =IF(F33<>"", VALUE(RIGHT(SUBSTITUTE(F33, "–", "-"), LEN(SUBSTITUTE(F33, "–", "-")) - FIND("-", SUBSTITUTE(F33, "–", "-")))), "") | L33: =L32+1 -> 33
A34: 2 | B34: Sat | C34: 2024-08-24 | D34: Aston Villa | E34: 1.2 | F34: 0–2 | G34: 0.9 | H34: Arsenal | I34: Villa Park | J34: =IF(F34<>"", VALUE(LEFT(SUBSTITUTE(F34, "–", "-"), FIND("-", SUBSTITUTE(F34, "–", "-")) - 1)), "") -> 0 | K34: =IF(F34<>"", VALUE(RIGHT(SUBSTITUTE(F34, "–", "-"), LEN(SUBSTITUTE(F34, "–", "-")) - FIND("-", SUBSTITUTE(F34, "–", "-")))), "") -> 2 | L34: =L33+1 -> 34
A35: 23 | B35: Sun | C35: 2025-01-26 | D35: Aston Villa | H35: West Ham | I35: Villa Park | J35: =IF(F35<>"", VALUE(LEFT(SUBSTITUTE(F35, "–", "-"), FIND("-", SUBSTITUTE(F35, "–", "-")) - 1)), "") | K35: =IF(F35<>"", VALUE(RIGHT(SUBSTITUTE(F35, "–", "-"), LEN(SUBSTITUTE(F35, "–", "-")) - FIND("-", SUBSTITUTE(F35, "–", "-")))), "") | L35: =L34+1 -> 35
A36: 25 | B36: Sat | C36: 2025-02-15 | D36: Aston Villa | H36: Ipswich Town | I36: Villa Park | J36: =IF(F36<>"", VALUE(LEFT(SUBSTITUTE(F36, "–", "-"), FIND("-", SUBSTITUTE(F36, "–", "-")) - 1)), "") | K36: =IF(F36<>"", VALUE(RIGHT(SUBSTITUTE(F36, "–", "-"), LEN(SUBSTITUTE(F36, "–", "-")) - FIND("-", SUBSTITUTE(F36, "–", "-")))), "") | L36: =L35+1 -> 36
A37: 37 | B37: Sun | C37: 2025-05-18 | D37: Aston Villa | H37: Tottenham | I37: Villa Park | J37: =IF(F37<>"", VALUE(LEFT(SUBSTITUTE(F37, "–", "-"), FIND("-", SUBSTITUTE(F37, "–", "-")) - 1)), "") | K37: =IF(F37<>"", VALUE(RIGHT(SUBSTITUTE(F37, "–", "-"), LEN(SUBSTITUTE(F37, "–", "-")) - FIND("-", SUBSTITUTE(F37, "–", "-")))), "") | L37: =L36+1 -> 37
A38: 12 | B38: Sat | C38: 2024-11-23 | D38: Aston Villa | H38: Crystal Palace | I38: Villa Park | J38: =IF(F38<>"", VALUE(LEFT(SUBSTITUTE(F38, "–", "-"), FIND("-", SUBSTITUTE(F38, "–", "-")) - 1)), "") | K38: =IF(F38<>"", VALUE(RIGHT(SUBSTITUTE(F38, "–", "-"), LEN(SUBSTITUTE(F38, "–", "-")) - FIND("-", SUBSTITUTE(F38, "–", "-")))), "") | L38: =L37+1 -> 38
A39: 9 | B39: Sat | C39: 2024-10-26 | D39: Aston Villa | E39: 1.8 | F39: 1–1 | G39: 0.3 | H39: Bournemouth | I39: Villa Park | J39: =IF(F39<>"", VALUE(LEFT(SUBSTITUTE(F39, "–", "-"), FIND("-", SUBSTITUTE(F39, "–", "-")) - 1)), "") -> 1 | K39: =IF(F39<>"", VALUE(RIGHT(SUBSTITUTE(F39, "–", "-"), LEN(SUBSTITUTE(F39, "–", "-")) - FIND("-", SUBSTITUTE(F39, "–", "-")))), "") -> 1 | L39: =L38+1 -> 39
A40: 24 | B40: Sat | C40: 2025-02-01 | D40: Bournemouth | H40: Liverpool | I40: Vitality Stadium | J40: =IF(F40<>"", VALUE(LEFT(SUBSTITUTE(F40, "–", "-"), FIND("-", SUBSTITUTE(F40, "–", "-")) - 1)), "") | K40: =IF(F40<>"", VALUE(RIGHT(SUBSTITUTE(F40, "–", "-"), LEN(SUBSTITUTE(F40, "–", "-")) - FIND("-", SUBSTITUTE(F40, "–", "-")))), "") | L40: =L39+1 -> 40
...

Sheet homeStats
A1: Wk | B1: Day | C1: Date | D1: Home | E1: xG | F1: Score | G1: xGa | H1: Away | I1: Venue | J1: Home goals | K1: Away goals
A2: =HLOOKUP(homeStats2!A$1,homeStats2!$A$1:$K$500,homeStats2!$L2,FALSE) -> 6 | B2: =HLOOKUP(homeStats2!B$1,homeStats2!$A$1:$K$500,homeStats2!$L2,FALSE) -> Sat | C2: =HLOOKUP(homeStats2!C$1,homeStats2!$A$1:$K$500,homeStats2!$L2,FALSE) -> 2024-09-28 | D2: =HLOOKUP(homeStats2!D$1,homeStats2!$A$1:$K$500,homeStats2!$L2,FALSE) -> Arsenal | E2: =HLOOKUP(homeStats2!E$1,homeStats2!$A$1:$K$500,homeStats2!$L2,FALSE) -> 4.4 | F2: =HLOOKUP(homeStats2!F$1,homeStats2!$A$1:$K$500,homeStats2!$L2,FALSE) -> 4–2 | G2: =HLOOKUP(homeStats2!G$1,homeStats2!$A$1:$K$500,homeStats2!$L2,FALSE) -> 0.3 | H2: =HLOOKUP(homeStats2!H$1,homeStats2!$A$1:$K$500,homeStats2!$L2,FALSE) -> Leicester City | ... K2: =HLOOKUP(homeStats2!K$1,homeStats2!$A$1:$K$500,homeStats2!$L2,FALSE) -> 2
A3: =HLOOKUP(homeStats2!A$1,homeStats2!$A$1:$K$500,homeStats2!$L3,FALSE) -> 30 | B3: =HLOOKUP(homeStats2!B$1,homeStats2!$A$1:$K$500,homeStats2!$L3,FALSE) -> Tue | C3: =HLOOKUP(homeStats2!C$1,homeStats2!$A$1:$K$500,homeStats2!$L3,FALSE) -> 2025-04-01 | D3: =HLOOKUP(homeStats2!D$1,homeStats2!$A$1:$K$500,homeStats2!$L3,FALSE) -> Arsenal | E3: =HLOOKUP(homeStats2!E$1,homeStats2!$A$1:$K$500,homeStats2!$L3,FALSE) | F3: =HLOOKUP(homeStats2!F$1,homeStats2!$A$1:$K$500,homeStats2!$L3,FALSE) | G3: =HLOOKUP(homeStats2!G$1,homeStats2!$A$1:$K$500,homeStats2!$L3,FALSE) | H3: =HLOOKUP(homeStats2!H$1,homeStats2!$A$1:$K$500,homeStats2!$L3,FALSE) -> Fulham | ... K3: =HLOOKUP(homeStats2!K$1,homeStats2!$A$1:$K$500,homeStats2!$L3,FALSE)
A4: =HLOOKUP(homeStats2!A$1,homeStats2!$A$1:$K$500,homeStats2!$L4,FALSE) -> 35 | B4: =HLOOKUP(homeStats2!B$1,homeStats2!$A$1:$K$500,homeStats2!$L4,FALSE) -> Sat | C4: =HLOOKUP(homeStats2!C$1,homeStats2!$A$1:$K$500,homeStats2!$L4,FALSE) -> 2025-05-03 | D4: =HLOOKUP(homeStats2!D$1,homeStats2!$A$1:$K$500,homeStats2!$L4,FALSE) -> Arsenal | E4: =HLOOKUP(homeStats2!E$1,homeStats2!$A$1:$K$500,homeStats2!$L4,FALSE) | F4: =HLOOKUP(homeStats2!F$1,homeStats2!$A$1:$K$500,homeStats2!$L4,FALSE) | G4: =HLOOKUP(homeStats2!G$1,homeStats2!$A$1:$K$500,homeStats2!$L4,FALSE) | H4: =HLOOKUP(homeStats2!H$1,homeStats2!$A$1:$K$500,homeStats2!$L4,FALSE) -> Bournemouth | ... K4: =HLOOKUP(homeStats2!K$1,homeStats2!$A$1:$K$500,homeStats2!$L4,FALSE)
A5: =HLOOKUP(homeStats2!A$1,homeStats2!$A$1:$K$500,homeStats2!$L5,FALSE) -> 18 | B5: =HLOOKUP(homeStats2!B$1,homeStats2!$A$1:$K$500,homeStats2!$L5,FALSE) -> Fri | C5: =HLOOKUP(homeStats2!C$1,homeStats2!$A$1:$K$500,homeStats2!$L5,FALSE) -> 2024-12-27 | D5: =HLOOKUP(homeStats2!D$1,homeStats2!$A$1:$K$500,homeStats2!$L5,FALSE) -> Arsenal | E5: =HLOOKUP(homeStats2!E$1,homeStats2!$A$1:$K$500,homeStats2!$L5,FALSE) | F5: =HLOOKUP(homeStats2!F$1,homeStats2!$A$1:$K$500,homeStats2!$L5,FALSE) | G5: =HLOOKUP(homeStats2!G$1,homeStats2!$A$1:$K$500,homeStats2!$L5,FALSE) | H5: =HLOOKUP(homeStats2!H$1,homeStats2!$A$1:$K$500,homeStats2!$L5,FALSE) -> Ipswich Town | ... K5: =HLOOKUP(homeStats2!K$1,homeStats2!$A$1:$K$500,homeStats2!$L5,FALSE)
A6: =HLOOKUP(homeStats2!A$1,homeStats2!$A$1:$K$500,homeStats2!$L6,FALSE) -> 16 | B6: =HLOOKUP(homeStats2!B$1,homeStats2!$A$1:$K$500,homeStats2!$L6,FALSE) -> Sat | C6: =HLOOKUP(homeStats2!C$1,homeStats2!$A$1:$K$500,homeStats2!$L6,FALSE) -> 2024-12-14 | D6: =HLOOKUP(homeStats2!D$1,homeStats2!$A$1:$K$500,homeStats2!$L6,FALSE) -> Arsenal | E6: =HLOOKUP(homeStats2!E$1,homeStats2!$A$1:$K$500,homeStats2!$L6,FALSE) | F6: =HLOOKUP(homeStats2!F$1,homeStats2!$A$1:$K$500,homeStats2!$L6,FALSE) | G6: =HLOOKUP(homeStats2!G$1,homeStats2!$A$1:$K$500,homeStats2!$L6,FALSE) | H6: =HLOOKUP(homeStats2!H$1,homeStats2!$A$1:$K$500,homeStats2!$L6,FALSE) -> Everton | ... K6: =HLOOKUP(homeStats2!K$1,homeStats2!$A$1:$K$500,homeStats2!$L6,FALSE)
A7: =HLOOKUP(homeStats2!A$1,homeStats2!$A$1:$K$500,homeStats2!$L7,FALSE) -> 37 | B7: =HLOOKUP(homeStats2!B$1,homeStats2!$A$1:$K$500,homeStats2!$L7,FALSE) -> Sun | C7: =HLOOKUP(homeStats2!C$1,homeStats2!$A$1:$K$500,homeStats2!$L7,FALSE) -> 2025-05-18 | D7: =HLOOKUP(homeStats2!D$1,homeStats2!$A$1:$K$500,homeStats2!$L7,FALSE) -> Arsenal | E7: =HLOOKUP(homeStats2!E$1,homeStats2!$A$1:$K$500,homeStats2!$L7,FALSE) | F7: =HLOOKUP(homeStats2!F$1,homeStats2!$A$1:$K$500,homeStats2!$L7,FALSE) | G7: =HLOOKUP(homeStats2!G$1,homeStats2!$A$1:$K$500,homeStats2!$L7,FALSE) | H7: =HLOOKUP(homeStats2!H$1,homeStats2!$A$1:$K$500,homeStats2!$L7,FALSE) -> Newcastle Utd | ... K7: =HLOOKUP(homeStats2!K$1,homeStats2!$A$1:$K$500,homeStats2!$L7,FALSE)
A8: =HLOOKUP(homeStats2!A$1,homeStats2!$A$1:$K$500,homeStats2!$L8,FALSE) -> 29 | B8: =HLOOKUP(homeStats2!B$1,homeStats2!$A$1:$K$500,homeStats2!$L8,FALSE) -> Sat | C8: =HLOOKUP(homeStats2!C$1,homeStats2!$A$1:$K$500,homeStats2!$L8,FALSE) -> 2025-03-15 | D8: =HLOOKUP(homeStats2!D$1,homeStats2!$A$1:$K$500,homeStats2!$L8,FALSE) -> Arsenal | E8: =HLOOKUP(homeStats2!E$1,homeStats2!$A$1:$K$500,homeStats2!$L8,FALSE) | F8: =HLOOKUP(homeStats2!F$1,homeStats2!$A$1:$K$500,homeStats2!$L8,FALSE) | G8: =HLOOKUP(homeStats2!G$1,homeStats2!$A$1:$K$500,homeStats2!$L8,FALSE) | H8: =HLOOKUP(homeStats2!H$1,homeStats2!$A$1:$K$500,homeStats2!$L8,FALSE) -> Chelsea | ... K8: =HLOOKUP(homeStats2!K$1,homeStats2!$A$1:$K$500,homeStats2!$L8,FALSE)
A9: =HLOOKUP(homeStats2!A$1,homeStats2!$A$1:$K$500,homeStats2!$L9,FALSE) -> 21 | B9: =HLOOKUP(homeStats2!B$1,homeStats2!$A$1:$K$500,homeStats2!$L9,FALSE) -> Wed | C9: =HLOOKUP(homeStats2!C$1,homeStats2!$A$1:$K$500,homeStats2!$L9,FALSE) -> 2025-01-15 | D9: =HLOOKUP(homeStats2!D$1,homeStats2!$A$1:$K$500,homeStats2!$L9,FALSE) -> Arsenal | E9: =HLOOKUP(homeStats2!E$1,homeStats2!$A$1:$K$500,homeStats2!$L9,FALSE) | F9: =HLOOKUP(homeStats2!F$1,homeStats2!$A$1:$K$500,homeStats2!$L9,FALSE) | G9: =HLOOKUP(homeStats2!G$1,homeStats2!$A$1:$K$500,homeStats2!$L9,FALSE) | H9: =HLOOKUP(homeStats2!H$1,homeStats2!$A$1:$K$500,homeStats2!$L9,FALSE) -> Tottenham | ... K9: =HLOOKUP(homeStats2!K$1,homeStats2!$A$1:$K$500,homeStats2!$L9,FALSE)
A10: =HLOOKUP(homeStats2!A$1,homeStats2!$A$1:$K$500,homeStats2!$L10,FALSE) -> 14 | B10: =HLOOKUP(homeStats2!B$1,homeStats2!$A$1:$K$500,homeStats2!$L10,FALSE) -> Wed | C10: =HLOOKUP(homeStats2!C$1,homeStats2!$A$1:$K$500,homeStats2!$L10,FALSE) -> 2024-12-04 | D10: =HLOOKUP(homeStats2!D$1,homeStats2!$A$1:$K$500,homeStats2!$L10,FALSE) -> Arsenal | E10: =HLOOKUP(homeStats2!E$1,homeStats2!$A$1:$K$500,homeStats2!$L10,FALSE) | F10: =HLOOKUP(homeStats2!F$1,homeStats2!$A$1:$K$500,homeStats2!$L10,FALSE) | G10: =HLOOKUP(homeStats2!G$1,homeStats2!$A$1:$K$500,homeStats2!$L10,FALSE) | H10: =HLOOKUP(homeStats2!H$1,homeStats2!$A$1:$K$500,homeStats2!$L10,FALSE) -> Manchester Utd | ... K10: =HLOOKUP(homeStats2!K$1,homeStats2!$A$1:$K$500,homeStats2!$L10,FALSE)
A11: =HLOOKUP(homeStats2!A$1,homeStats2!$A$1:$K$500,homeStats2!$L11,FALSE) -> 32 | B11: =HLOOKUP(homeStats2!B$1,homeStats2!$A$1:$K$500,homeStats2!$L11,FALSE) -> Sat | C11: =HLOOKUP(homeStats2!C$1,homeStats2!$A$1:$K$500,homeStats2!$L11,FALSE) -> 2025-04-12 | D11: =HLOOKUP(homeStats2!D$1,homeStats2!$A$1:$K$500,homeStats2!$L11,FALSE) -> Arsenal | E11: =HLOOKUP(homeStats2!E$1,homeStats2!$A$1:$K$500,homeStats2!$L11,FALSE) | F11: =HLOOKUP(homeStats2!F$1,homeStats2!$A$1:$K$500,homeStats2!$L11,FALSE) | G11: =HLOOKUP(homeStats2!G$1,homeStats2!$A$1:$K$500,homeStats2!$L11,FALSE) | H11: =HLOOKUP(homeStats2!H$1,homeStats2!$A$1:$K$500,homeStats2!$L11,FALSE) -> Brentford | ... K11: =HLOOKUP(homeStats2!K$1,homeStats2!$A$1:$K$500,homeStats2!$L11,FALSE)
A12: =HLOOKUP(homeStats2!A$1,homeStats2!$A$1:$K$500,homeStats2!$L12,FALSE) -> 22 | B12: =HLOOKUP(homeStats2!B$1,homeStats2!$A$1:$K$500,homeStats2!$L12,FALSE) -> Sat | C12: =HLOOKUP(homeStats2!C$1,homeStats2!$A$1:$K$500,homeStats2!$L12,FALSE) -> 2025-01-18 | D12: =HLOOKUP(homeStats2!D$1,homeStats2!$A$1:$K$500,homeStats2!$L12,FALSE) -> Arsenal | E12: =HLOOKUP(homeStats2!E$1,homeStats2!$A$1:$K$500,homeStats2!$L12,FALSE) | F12: =HLOOKUP(homeStats2!F$1,homeStats2!$A$1:$K$500,homeStats2!$L12,FALSE) | G12: =HLOOKUP(homeStats2!G$1,homeStats2!$A$1:$K$500,homeStats2!$L12,FALSE) | H12: =HLOOKUP(homeStats2!H$1,homeStats2!$A$1:$K$500,homeStats2!$L12,FALSE) -> Aston Villa | ... K12: =HLOOKUP(homeStats2!K$1,homeStats2!$A$1:$K$500,homeStats2!$L12,FALSE)
A13: =HLOOKUP(homeStats2!A$1,homeStats2!$A$1:$K$500,homeStats2!$L13,FALSE) -> 9 | B13: =HLOOKUP(homeStats2!B$1,homeStats2!$A$1:$K$500,homeStats2!$L13,FALSE) -> Sun | C13: =HLOOKUP(homeStats2!C$1,homeStats2!$A$1:$K$500,homeStats2!$L13,FALSE) -> 2024-10-27 | D13: =HLOOKUP(homeStats2!D$1,homeStats2!$A$1:$K$500,homeStats2!$L13,FALSE) -> Arsenal | E13: =HLOOKUP(homeStats2!E$1,homeStats2!$A$1:$K$500,homeStats2!$L13,FALSE) -> 0.9 | F13: =HLOOKUP(homeStats2!F$1,homeStats2!$A$1:$K$500,homeStats2!$L13,FALSE) -> 2–2 | G13: =HLOOKUP(homeStats2!G$1,homeStats2!$A$1:$K$500,homeStats2!$L13,FALSE) -> 0.8 | H13: =HLOOKUP(homeStats2!H$1,homeStats2!$A$1:$K$500,homeStats2!$L13,FALSE) -> Liverpool | ... K13: =HLOOKUP(homeStats2!K$1,homeStats2!$A$1:$K$500,homeStats2!$L13,FALSE) -> 2
... A381: =HLOOKUP(homeStats2!A$1,homeStats2!$A$1:$K$500,homeStats2!$L381,FALSE) -> 11 | B381: =HLOOKUP(homeStats2!B$1,homeStats2!$A$1:$K$500,homeStats2!$L381,FALSE) -> Sat | C381: =HLOOKUP(homeStats2!C$1,homeStats2!$A$1:$K$500,homeStats2!$L381,FALSE) -> 2024-11-09 | D381: =HLOOKUP(homeStats2!D$1,homeStats2!$A$1:$K$500,homeStats2!$L381,FALSE) -> Wolves | E381: =HLOOKUP(homeStats2!E$1,homeStats2!$A$1:$K$500,homeStats2!$L381,FALSE) | F381: =HLOOKUP(homeStats2!F$1,homeStats2!$A$1:$K$500,homeStats2!$L381,FALSE) | G381: =HLOOKUP(homeStats2!G$1,homeStats2!$A$1:$K$500,homeStats2!$L381,FALSE) | H381: =HLOOKUP(homeStats2!H$1,homeStats2!$A$1:$K$500,homeStats2!$L381,FALSE) -> Southampton | ... K381: =HLOOKUP(homeStats2!K$1,homeStats2!$A$1:$K$500,homeStats2!$L381,FALSE)

Sheet awayStats
A1: Wk | B1: Day | C1: Date | D1: Home | E1: xG | F1: Score | G1: xGa | H1: Away | I1: Venue | J1: Home goals | K1: Away goals
A2: =HLOOKUP(awayStats2!A$1,awayStats2!$A$1:$K$500,awayStats2!$L2,FALSE) -> 19 | B2: =HLOOKUP(awayStats2!B$1,awayStats2!$A$1:$K$500,awayStats2!$L2,FALSE) -> Wed | C2: =HLOOKUP(awayStats2!C$1,awayStats2!$A$1:$K$500,awayStats2!$L2,FALSE) -> 2025-01-01 | D2: =HLOOKUP(awayStats2!D$1,awayStats2!$A$1:$K$500,awayStats2!$L2,FALSE) -> Brentford | E2: =HLOOKUP(awayStats2!E$1,awayStats2!$A$1:$K$500,awayStats2!$L2,FALSE) | F2: =HLOOKUP(awayStats2!F$1,awayStats2!$A$1:$K$500,awayStats2!$L2,FALSE) | G2: =HLOOKUP(awayStats2!G$1,awayStats2!$A$1:$K$500,awayStats2!$L2,FALSE) | H2: =HLOOKUP(awayStats2!H$1,awayStats2!$A$1:$K$500,awayStats2!$L2,FALSE) -> Arsenal | ... K2: =HLOOKUP(awayStats2!K$1,awayStats2!$A$1:$K$500,awayStats2!$L2,FALSE)
A3: =HLOOKUP(awayStats2!A$1,awayStats2!$A$1:$K$500,awayStats2!$L3,FALSE) -> 11 | B3: =HLOOKUP(awayStats2!B$1,awayStats2!$A$1:$K$500,awayStats2!$L3,FALSE) -> Sun | C3: =HLOOKUP(awayStats2!C$1,awayStats2!$A$1:$K$500,awayStats2!$L3,FALSE) -> 2024-11-10 | D3: =HLOOKUP(awayStats2!D$1,awayStats2!$A$1:$K$500,awayStats2!$L3,FALSE) -> Chelsea | E3: =HLOOKUP(awayStats2!E$1,awayStats2!$A$1:$K$500,awayStats2!$L3,FALSE) | F3: =HLOOKUP(awayStats2!F$1,awayStats2!$A$1:$K$500,awayStats2!$L3,FALSE) | G3: =HLOOKUP(awayStats2!G$1,awayStats2!$A$1:$K$500,awayStats2!$L3,FALSE) | H3: =HLOOKUP(awayStats2!H$1,awayStats2!$A$1:$K$500,awayStats2!$L3,FALSE) -> Arsenal | ... K3: =HLOOKUP(awayStats2!K$1,awayStats2!$A$1:$K$500,awayStats2!$L3,FALSE)
A4: =HLOOKUP(awayStats2!A$1,awayStats2!$A$1:$K$500,awayStats2!$L4,FALSE) -> 13 | B4: =HLOOKUP(awayStats2!B$1,awayStats2!$A$1:$K$500,awayStats2!$L4,FALSE) -> Sat | C4: =HLOOKUP(awayStats2!C$1,awayStats2!$A$1:$K$500,awayStats2!$L4,FALSE) -> 2024-11-30 | D4: =HLOOKUP(awayStats2!D$1,awayStats2!$A$1:$K$500,awayStats2!$L4,FALSE) -> West Ham | E4: =HLOOKUP(awayStats2!E$1,awayStats2!$A$1:$K$500,awayStats2!$L4,FALSE) | F4: =HLOOKUP(awayStats2!F$1,awayStats2!$A$1:$K$500,awayStats2!$L4,FALSE) | G4: =HLOOKUP(awayStats2!G$1,awayStats2!$A$1:$K$500,awayStats2!$L4,FALSE) | H4: =HLOOKUP(awayStats2!H$1,awayStats2!$A$1:$K$500,awayStats2!$L4,FALSE) -> Arsenal | ... K4: =HLOOKUP(awayStats2!K$1,awayStats2!$A$1:$K$500,awayStats2!$L4,FALSE)
A5: =HLOOKUP(awayStats2!A$1,awayStats2!$A$1:$K$500,awayStats2!$L5,FALSE) -> 8 | B5: =HLOOKUP(awayStats2!B$1,awayStats2!$A$1:$K$500,awayStats2!$L5,FALSE) -> Sat | C5: =HLOOKUP(awayStats2!C$1,awayStats2!$A$1:$K$500,awayStats2!$L5,FALSE) -> 2024-10-19 | D5: =HLOOKUP(awayStats2!D$1,awayStats2!$A$1:$K$500,awayStats2!$L5,FALSE) -> Bournemouth | E5: =HLOOKUP(awayStats2!E$1,awayStats2!$A$1:$K$500,awayStats2!$L5,FALSE) -> 1.8 | F5: =HLOOKUP(awayStats2!F$1,awayStats2!$A$1:$K$500,awayStats2!$L5,FALSE) -> 2–0 | G5: =HLOOKUP(awayStats2!G$1,awayStats2!$A$1:$K$500,awayStats2!$L5,FALSE) -> 0.7 | H5: =HLOOKUP(awayStats2!H$1,awayStats2!$A$1:$K$500,awayStats2!$L5,FALSE) -> Arsenal | ... K5: =HLOOKUP(awayStats2!K$1,awayStats2!$A$1:$K$500,awayStats2!$L5,FALSE) -> 0
A6: =HLOOKUP(awayStats2!A$1,awayStats2!$A$1:$K$500,awayStats2!$L6,FALSE) -> 15 | B6: =HLOOKUP(awayStats2!B$1,awayStats2!$A$1:$K$500,awayStats2!$L6,FALSE) -> Sun | C6: =HLOOKUP(awayStats2!C$1,awayStats2!$A$1:$K$500,awayStats2!$L6,FALSE) -> 2024-12-08 | D6: =HLOOKUP(awayStats2!D$1,awayStats2!$A$1:$K$500,awayStats2!$L6,FALSE) -> Fulham | E6: =HLOOKUP(awayStats2!E$1,awayStats2!$A$1:$K$500,awayStats2!$L6,FALSE) | F6: =HLOOKUP(awayStats2!F$1,awayStats2!$A$1:$K$500,awayStats2!$L6,FALSE) | G6: =HLOOKUP(awayStats2!G$1,awayStats2!$A$1:$K$500,awayStats2!$L6,FALSE) | H6: =HLOOKUP(awayStats2!H$1,awayStats2!$A$1:$K$500,awayStats2!$L6,FALSE) -> Arsenal | ... K6: =HLOOKUP(awayStats2!K$1,awayStats2!$A$1:$K$500,awayStats2!$L6,FALSE)
A7: =HLOOKUP(awayStats2!A$1,awayStats2!$A$1:$K$500,awayStats2!$L7,FALSE) -> 17 | B7: =HLOOKUP(awayStats2!B$1,awayStats2!$A$1:$K$500,awayStats2!$L7,FALSE) -> Sat | C7: =HLOOKUP(awayStats2!C$1,awayStats2!$A$1:$K$500,awayStats2!$L7,FALSE) -> 2024-12-21 | D7: =HLOOKUP(awayStats2!D$1,awayStats2!$A$1:$K$500,awayStats2!$L7,FALSE) -> Crystal Palace | E7: =HLOOKUP(awayStats2!E$1,awayStats2!$A$1:$K$500,awayStats2!$L7,FALSE) | F7: =HLOOKUP(awayStats2!F$1,awayStats2!$A$1:$K$500,awayStats2!$L7,FALSE) | G7: =HLOOKUP(awayStats2!G$1,awayStats2!$A$1:$K$500,awayStats2!$L7,FALSE) | H7: =HLOOKUP(awayStats2!H$1,awayStats2!$A$1:$K$500,awayStats2!$L7,FALSE) -> Arsenal | ... K7: =HLOOKUP(awayStats2!K$1,awayStats2!$A$1:$K$500,awayStats2!$L7,FALSE)
A8: =HLOOKUP(awayStats2!A$1,awayStats2!$A$1:$K$500,awayStats2!$L8,FALSE) -> 20 | B8: =HLOOKUP(awayStats2!B$1,awayStats2!$A$1:$K$500,awayStats2!$L8,FALSE) -> Sat | C8: =HLOOKUP(awayStats2!C$1,awayStats2!$A$1:$K$500,awayStats2!$L8,FALSE) -> 2025-01-04 | D8: =HLOOKUP(awayStats2!D$1,awayStats2!$A$1:$K$500,awayStats2!$L8,FALSE) -> Brighton | E8: =HLOOKUP(awayStats2!E$1,awayStats2!$A$1:$K$500,awayStats2!$L8,FALSE) | F8: =HLOOKUP(awayStats2!F$1,awayStats2!$A$1:$K$500,awayStats2!$L8,FALSE) | G8: =HLOOKUP(awayStats2!G$1,awayStats2!$A$1:$K$500,awayStats2!$L8,FALSE) | H8: =HLOOKUP(awayStats2!H$1,awayStats2!$A$1:$K$500,awayStats2!$L8,FALSE) -> Arsenal | ... K8: =HLOOKUP(awayStats2!K$1,awayStats2!$A$1:$K$500,awayStats2!$L8,FALSE)
A9: =HLOOKUP(awayStats2!A$1,awayStats2!$A$1:$K$500,awayStats2!$L9,FALSE) -> 5 | B9: =HLOOKUP(awayStats2!B$1,awayStats2!$A$1:$K$500,awayStats2!$L9,FALSE) -> Sun | C9: =HLOOKUP(awayStats2!C$1,awayStats2!$A$1:$K$500,awayStats2!$L9,FALSE) -> 2024-09-22 | D9: =HLOOKUP(awayStats2!D$1,awayStats2!$A$1:$K$500,awayStats2!$L9,FALSE) -> Manchester City | E9: =HLOOKUP(awayStats2!E$1,awayStats2!$A$1:$K$500,awayStats2!$L9,FALSE) -> 2.1 | F9: =HLOOKUP(awayStats2!F$1,awayStats2!$A$1:$K$500,awayStats2!$L9,FALSE) -> 2–2 | G9: =HLOOKUP(awayStats2!G$1,awayStats2!$A$1:$K$500,awayStats2!$L9,FALSE) -> 0.7 | H9: =HLOOKUP(awayStats2!H$1,awayStats2!$A$1:$K$500,awayStats2!$L9,FALSE) -> Arsenal | ... K9: =HLOOKUP(awayStats2!K$1,awayStats2!$A$1:$K$500,awayStats2!$L9,FALSE) -> 2
A10: =HLOOKUP(awayStats2!A$1,awayStats2!$A$1:$K$500,awayStats2!$L10,FALSE) -> 23 | B10: =HLOOKUP(awayStats2!B$1,awayStats2!$A$1:$K$500,awayStats2!$L10,FALSE) -> Sat | C10: =HLOOKUP(awayStats2!C$1,awayStats2!$A$1:$K$500,awayStats2!$L10,FALSE) -> 2025-01-25 | D10: =HLOOKUP(awayStats2!D$1,awayStats2!$A$1:$K$500,awayStats2!$L10,FALSE) -> Wolves | E10: =HLOOKUP(awayStats2!E$1,awayStats2!$A$1:$K$500,awayStats2!$L10,FALSE) | F10: =HLOOKUP(awayStats2!F$1,awayStats2!$A$1:$K$500,awayStats2!$L10,FALSE) | G10: =HLOOKUP(awayStats2!G$1,awayStats2!$A$1:$K$500,awayStats2!$L10,FALSE) | H10: =HLOOKUP(awayStats2!H$1,awayStats2!$A$1:$K$500,awayStats2!$L10,FALSE) -> Arsenal | ... K10: =HLOOKUP(awayStats2!K$1,awayStats2!$A$1:$K$500,awayStats2!$L10,FALSE)
